<mujoco model="Bipedal_V2">
    <option gravity="0 0 -9.81" />

    <!-- meshdir define the direction to mesh(.stl) files -->
    <compiler angle="degree" meshdir="meshes/" autolimits="true" /> 

    <option timestep="0.001"> </option>  <!-- set time step to 1ms-->
    <statistic extent="0.3" center="0.3 0 0" meansize=".03" /> <!-- dont care-->

    <contact> <!-- set contact between the foots and ground-->
        <pair geom1="ground" geom2="Left_Foot" solimp="0.95 0.95 0.0001" solref="0.0001 1" />
        <pair geom1="ground" geom2="Right_Foot" solimp="0.95 0.95 0.0001" solref="0.0001 1" />
    </contact>

    <default>
        <geom type="mesh" />
    </default>

    <default> <!-- for visual, not important-->
        <default class="visual">
            <geom contype="0" conaffinity="0" group="0" density="0" rgba="0.5 0.5 0.5 1" />
        </default>
        <default class="transparent">
            <geom contype="0" conaffinity="0" group="0" density="0" rgba="0.5 0.5 0.5 0.3" />
        </default>
        <default class="collision">
            <geom group="0" rgba="0.7 0.7 0.7 1" />
        </default>
    </default>

    <default> <!-- set properties for the actuators-->
        <default class="AK8064_actuator">
            <joint damping="0.02" armature="0.231" frictionloss="0.5" />
        </default>

        <default class="AK7010_actuator">
            <joint damping="0.015" armature="0.00414" frictionloss="0.35" />
        </default>

        <default class="AK109_actuator">
            <joint damping="0.015" armature="0.00812" frictionloss="0.5" />
        </default>

        <default class="AK606_actuator">
            <joint damping="0.005" armature="0.00088" frictionloss="0.15" />
        </default>
    </default>

    <!--   Define the mesh files below -->
    <!--   Fusion outputs meshes with mm units by default, therefore, scale to 0.001-->
    <asset>
        <!--   Torso  -->
        <mesh name="Torso"
            file="Torso.stl"
            scale="0.001 0.001 0.001" />
        <mesh name="Pelvis"
            file="Pelvis.stl"
            scale="0.001 0.001 0.001" />
        <!--   Waist  -->
        <mesh name="Waist_Pitch"
            file="Waist_Pitch.stl"
            scale="0.001 0.001 0.001" />
        <mesh name="Waist_Roll"
            file="Waist_Roll.stl"
            scale="0.001 0.001 0.001" />
        <!--   Leg stl file  -->
        <mesh name="HipLink1"
            file="Hip_Link1.stl"
            scale="0.001 0.001 0.001" />
        <mesh name="HipLink2"
            file="Hip_Link2.stl"
            scale="0.001 0.001 0.001" />
        <mesh name="Right_Thigh"
            file="Right_Thigh_Straight.stl"
            scale="0.001 0.001 0.001" />
        <mesh name="Left_Thigh"
            file="Left_Thigh_Straight.stl"
            scale="0.001 0.001 0.001" />
        <mesh name="Shank"
            file="Shank.stl"
            scale="0.001 0.001 0.001" />
        <!--   Ankle and Foot stl file  -->
        <mesh name="Ankle_Joint"
            file="Ankle_Joint.stl"
            scale="0.001 0.001 0.001" />
        <mesh name="Foot"
            file="Foot_v1.stl"
            scale="0.001 0.001 0.001" />
    </asset>

    <!-- for visual, not important-->
    <visual>
        <headlight diffuse="0.6 0.6 0.6" ambient="0.3 0.3 0.3" specular="0 0 0" />
        <rgba haze="0.15 0.25 0.35 1" />
        <global azimuth="-130" elevation="-20" />
    </visual>

    <!-- for visual, not important-->
    <asset>
        <texture builtin="gradient" height="100" rgb1=".4 .5 .6" rgb2="0 0 0" type="skybox"
            width="100" />
        <texture name="texplane" type="2d" builtin="checker" rgb1=".2 .3 .4" rgb2=".1 0.15 0.2"
            width="100" height="100" />
        <material name="MatPlane" reflectance="0.5" texture="texplane" texrepeat="1 1"
            texuniform="true" />         
    </asset>


    <!-- Start configuring the Model's Kinematic Tree here-->
    <worldbody>
        <!--  Ground/Floor -->
        <geom name="ground" pos="0 0 0" size="5 5 0.05" type="plane" material = "MatPlane"
            friction= "1 1 0.1" condim="3" conaffinity="1" contype="1" group="2"
            rgba="0.8 0.9 0.8 1" />
        
        <light cutoff="1000" diffuse="1 1 1" dir="-0 0 -1.3" directional="true" exponent="1"
            pos="0 0 1.3" specular=".1 .1 .1" castshadow="false" /> <!-- for visual -->

        <!--   Torso -->
        <body name="Torso" pos="0 0 0.83" euler="0 0 -90" >            
            <geom type="mesh" class="transparent" mesh="Torso" />
           <freejoint name="root" /> <!--   comment out this joint if we want to fix the torso -->
            <inertial pos="0 0 162.6E-3" mass="5.208" fullinertia="0.2985E-1 0.294E-1 0.31475E-1 0 0 0" />
            <site name="IMU" type = "box" pos="0 0 -0.1" size="0.01 0.01 0.01" rgba="1 0 0 1"/> <!--   this is to assign/locate an IMU sensor -->

            <!--   Pelvis, fixed to the torso  -->
            <body name="Pelvis" pos="0 0 0.013" euler="0 0 -90" >
                <geom type="mesh" class="visual" mesh="Pelvis" pos="0 0 0" name = "Pelvis"/>
                <inertial pos="0 0 -82.9E-3" mass="5.0425"
                    fullinertia="3.273E-2 1.921E-2 3.257E-2 2934.62E-9 85859.4E-9 -1312.919E-9" />

                <!--   Right leg kinematic chain  -->
                <body name="Right_Hip_link01" pos="0 0.170807 -0.128278" euler="-105 0 -90">  <!-- euler = "-90/105 0 -90" for normal/offset perpendicular axis -->
                    <!--   Hip link 1, set euler angle to rotate the body   -->
                    <joint type="hinge" name="Right_Hip_Flex" axis="0 0 -1" pos="0 0 -0.075"
                        range="-180 180" class = "AK109_actuator"/>
                    <geom type="mesh" class="visual" mesh="HipLink1" />
                    <inertial pos="0.000612 -0.004802 -0.013967" mass="1.792078"
                        fullinertia="0.003453 0.003288 0.002332 -0.63755E-5 -0.0975E-5 1.202E-4" />

                    <!--   Hip link 2 -->
                    <body name="Right_Hip_link02" pos="0 0 0" euler="90 0 75">   <!-- euler = "90 0 90/75" for normal/offset perpendicular axis -->                     
                         <joint type="hinge" name="Right_Hip_Abd" axis="0 0 1" pos="0 0 0"
                            range="-50 50" class = "AK7010_actuator"/> 
                        <geom type="mesh" class="visual" mesh="HipLink2" />
                        <inertial pos="-0.037E-3 72.145E-3 0.037E-3" mass="1.1418658"
                            fullinertia="3.056E-3 2.040E-3 2.335E-3 -0.758513E-6 -0.1156E-5 0.758095E-6" />

                        <!--   Thigh -->
                        <body name="Right_Thigh" pos="0 0.1395 0" euler="90 0 90">
                            <joint type="hinge" name="Right_Hip_Int" axis="0 0 -1"
                                pos="0 0 0" range="-180 180" class = "AK7010_actuator"/>

                            <geom type="mesh" class="visual" mesh="Right_Thigh" />

                            <inertial pos="5.715E-3 -14.644E-3 -72.428E-3" mass="1.757"
                                fullinertia="8.511E-3 8.797E-3 2.111E-3 -1.514E-4 7.111E-4 6.054E-4" />
                            <!--  Shank -->
                            <body name="Right_Shank" pos="0 0 -0.2" euler="90 0 0">
                                <joint type="hinge" name="Right_Knee" axis="0 0 -1"
                                    pos="0 0 0" range="-180 180" class = "AK109_actuator"/>
                                <geom type="mesh" class="visual" mesh="Shank" />
                                <inertial pos="0.018E-3 -106.616E-3 0.0" mass="1.5667"
                                    fullinertia="7.64E-3 1.897E-3 6.7E-3 24195.303E-9 321.924E-9 2097.433E-9" />
                                <!--  Ankle joint -->
                                <body name="Right_Ankle_Joint" pos="0 -0.321695 0"
                                    euler="90 0 0">
                                    <joint type="hinge" name="Right_Roll_Ankle" axis="1 0 0"
                                        pos="0 0 0" range="-180 180" class = "AK606_actuator"/>
                                    <geom type="mesh" class="visual"
                                        mesh="Ankle_Joint" />
                                    <inertial pos="0 0 0" mass="0.116"
                                        fullinertia="0.25355E-4 0.16344E-4 0.16467E-4 0.0 0.0 0.0" />
                                    <!--  Foot -->
                                    <body name="Right_Foot" pos="0 0 0"
                                        euler="90 0 90">
                                        <joint type="hinge" name="Right_Pitch_Ankle"
                                            axis="0 0 1" pos="0 0 0" range="-180 180" class = "AK606_actuator"/>
                                        <geom name = "Right_Foot" type="mesh" class="collision"
                                            mesh="Foot" friction= "1.1 1.1 0.1" />
                                        <inertial mass="0.35" pos="35.156E-3 -8.811E-3 0"
                                            fullinertia="0.8202E-3 1.764E-4 0.7512E-3 44169.168E-9 -1.081E-9 -1.66E-9" />                               
                                    </body>
                                </body>
                            </body>
                        </body>
                    </body>
                </body>
                <!--   Left leg kinematic chain  -->
                <body name="Left_Hip_link01" pos="0 -0.170807 -0.128278" euler="105 0 90">
                    <!--   Hip link 1, set euler angle to rotate the body   -->
                    <joint type="hinge" name="Left_Hip_Flex" axis="0 0 1" pos="0 0 -0.075"
                        range="-90 90" class = "AK109_actuator"/>
                    <geom type="mesh" class="visual" mesh="HipLink1" />
                    <inertial pos="0.000612 -0.004802 -0.013967" mass="1.792078"
                        fullinertia="0.003453 0.003288 0.002332 -0.63755E-5 -0.0975E-5 1.202E-4" />
                    <body name="Left_Hip_link02" pos="0 0 0" euler="90 0 75">
                        <!--   Hip link 2 -->
                        <joint type="hinge" name="Left_Hip_Abd" axis="0 0 -1" pos="0 0 0"
                            range="-30 60" class = "AK7010_actuator"/>
                        <geom type="mesh" class="visual" mesh="HipLink2" />
                        <inertial pos="-0.037E-3 72.145E-3 0.037E-3" mass="1.1418658"
                            fullinertia="3.056E-3 2.040E-3 2.335E-3 -0.758513E-6 -0.1156E-5 0.758095E-6" />
                        <!--   Thigh -->
                        <body name="Left_Thigh" pos="0 0.1395 0" euler="90 0 -90">
                            <joint type="hinge" name="Left_Hip_Int" axis="0 0 1"
                                pos="0 0 0" range="-45 45" class = "AK7010_actuator"/>
                            <geom type="mesh" class="visual" mesh="Left_Thigh" />
                            <inertial pos="5.715E-3 -14.644E-3 -72.428E-3" mass="1.757"
                                fullinertia="8.511E-3 8.797E-3 2.111E-3 -1.514E-4 7.111E-4 6.054E-4" />
                            <!--  Shank -->
                            <body name="Left_Shank" pos="0 0 -0.2" euler="90 0 0">
                                <joint type="hinge" name="Left_Knee" axis="0 0 -1"
                                    pos="0 0 0" range="-10 120" class = "AK109_actuator"/>
                                <geom type="mesh" class="visual" mesh="Shank"/>
                                <inertial pos="0.018E-3 -106.616E-3 0.0" mass="1.5667"
                                    fullinertia="7.64E-3 1.897E-3 6.7E-3 24195.303E-9 321.924E-9 2097.433E-9" />
                                <!--  Ankle joint -->
                                <body name="Left_Ankle_Joint" pos="0 -0.321695 0"
                                    euler="90 0 0">
                                    <joint type="hinge" name="Left_Roll_Ankle"
                                        axis="1 0 0" pos="0 0 0" range="-180 180" class = "AK606_actuator"/>
                                    <geom type="mesh" class="visual"
                                        mesh="Ankle_Joint" />
                                    <inertial pos="0 0 0" mass="0.116"
                                        fullinertia="16260.707E-9 9027.185E-9 17297.275E-9 0.0 0.0 0.0" />
                                    <!--  Foot  -->
                                    <body name="Left_Foot" pos="0 0 0"
                                        euler="90 0 90">
                                        <joint type="hinge" name="Left_Pitch_Ankle"
                                            axis="0 0 1" pos="0 0 0" range="-180 180"
                                            actuatorfrcrange="-30 45" class = "AK606_actuator"/>
                                        <geom name = "Left_Foot" type="mesh" class="collision"
                                            mesh="Foot" friction = "1.1 1.1 0.1"/>
                                        <inertial mass="0.35" pos="35.156E-3 -8.811E-3 0"
                                            fullinertia="0.8202E-3 1.764E-4 0.7512E-3 44169.168E-9 -1.081E-9 -1.66E-9" />
                                    </body>
                                </body>
                            </body>
                        </body>
                    </body>
                </body>
            </body>
        </body>
        <!--   End of 2 legs  -->
    </worldbody>
    <!--   End of Model's Kinematic Tree  -->

    <contact> <!--   Exclude other contact, to reduce computation, dont care other contacts  -->
        <exclude body1="Torso" body2="Right_Hip_link01" />
        <exclude body1="Torso" body2="Right_Hip_link02" />
        <exclude body1="Torso" body2="Left_Thigh" />
        <exclude body1="Right_Hip_link01" body2="Right_Hip_link02" />
        <exclude body1="Right_Hip_link02" body2="Left_Thigh" />
        <exclude body1="Left_Thigh" body2="Left_Shank" />
        <exclude body1="Left_Shank" body2="Left_Ankle_Joint" />
        <exclude body1="Left_Ankle_Joint" body2="Left_Foot" />
        <exclude body1="Torso" body2="Left_Hip_link01" />
        <exclude body1="Torso" body2="Left_Hip_link02" />
        <exclude body1="Torso" body2="Right_Thigh" />
        <exclude body1="Left_Hip_link01" body2="Left_Hip_link02" />
        <exclude body1="Left_Hip_link02" body2="Right_Thigh" />
        <exclude body1="Right_Thigh" body2="Left_Shank" />
        <exclude body1="Left_Shank" body2="Left_Ankle_Joint" />
        <exclude body1="Left_Ankle_Joint" body2="Left_Foot" />
        <exclude body1="Left_Thigh" body2="Right_Thigh" />
        <exclude body1="Right_Shank" body2="Left_Shank" />
    </contact>

    <!--   Define actuator for each joint -->
    <actuator>
        <motor name="Right_Hip_Flex_m" joint="Right_Hip_Flex" ctrlrange="-120 120" />        
        <motor name="Right_Hip_Abd_m" joint="Right_Hip_Abd" ctrlrange="-45 45" />        
        <motor name="Right_Hip_Int_m" joint="Right_Hip_Int" ctrlrange="-24 24" />
        <motor name="Right_Knee_m" joint="Right_Knee" ctrlrange="-60 60" />
        <motor name="Right_Ank_Pitch_m" joint="Right_Pitch_Ankle" ctrlrange="-30 30" />
        <motor name="Right_Ank_Roll_m" joint="Right_Roll_Ankle" ctrlrange="-30 30" />

        <motor name="Left_Hip_Flex_m" joint="Left_Hip_Flex" ctrlrange="-120 120" />
        <motor name="Left_Hip_Abd_m" joint="Left_Hip_Abd" ctrlrange="-45 45" />
        <motor name="Left_Hip_Int_m" joint="Left_Hip_Int" ctrlrange="-24 24" />
        <motor name="Left_Knee_m" joint="Left_Knee" ctrlrange="-60 60" />
        <motor name="Left_Ank_Pitch_m" joint="Left_Pitch_Ankle" ctrlrange="-30 30" />
        <motor name="Left_Ank_Roll_m" joint="Left_Roll_Ankle" ctrlrange="-30 30" />
    </actuator>

    <sensor> <!--   optional, add sensor if needed, we can get sensor's values in the code -->
        <accelerometer name="accel" site="IMU"/>
        <gyro name="gyro" site="IMU"/>
        <velocimeter name="velmeter" site="IMU"/> 
    </sensor>

</mujoco>