<mujoco model="Bipedal_V2">
    <option gravity="0 0 -9.81" />
    <compiler angle="degree" meshdir="meshes/" autolimits="true" />
    <!-- discardvisual="True"  -->

    <option timestep="0.001"></option>
    <statistic extent="0.3" center="0.3 0 0" meansize=".03" />

    <contact>
        <pair geom1="ground" geom2="Left_Foot" solimp="0.95 0.95 0.0001" solref="0.0001 1" />
        <pair geom1="ground" geom2="Right_Foot" solimp="0.95 0.95 0.0001" solref="0.0001 1" />
    </contact>

    <default>
        <geom type="mesh" />
    </default>
    <default>
        <default class="visual">
            <geom contype="0" conaffinity="0" group="0" density="0" rgba="0.5 0.5 0.5 1" />
        </default>
        <default class="transparent">
            <geom contype="0" conaffinity="0" group="0" density="0" rgba="0.5 0.5 0.5 0.3" />
        </default>
        <default class="collision">
            <geom group="0" rgba="0.7 0.7 0.7 1" />
        </default>
    </default>

    <default>
        <default class="AK8064_actuator">
            <joint damping="0.02" armature="0.231" frictionloss="0.25" />
        </default>

        <default class="AK7010_actuator">
            <joint damping="0.015" armature="0.00414" frictionloss="0.35" />
        </default>

        <default class="AK109_actuator">
            <joint damping="0.015" armature="0.00812" frictionloss="0.25" />
        </default>

        <default class="AK606_actuator">
            <joint damping="0.005" armature="0.00088" frictionloss="0.15" />
        </default>
    </default>

    <!--   Fusion outputs meshes with mm units by default, but must be converted to m in MuJoCo, hence
    the scaling   -->
    <asset>
        <!--   Torso  -->
        <mesh name="Torso" file="Torso.stl" scale="0.001 0.001 0.001" />
        <mesh name="Pelvis" file="Pelvis.stl" scale="0.001 0.001 0.001" />
        <!--   Waist  -->
        <mesh name="Waist_Pitch" file="Waist_Pitch.stl" scale="0.001 0.001 0.001" />
        <mesh name="Waist_Roll" file="Waist_Roll.stl" scale="0.001 0.001 0.001" />
        <!--   Leg stl file  -->
        <mesh name="HipLink1" file="Hip_Link1.stl" scale="0.001 0.001 0.001" />
        <mesh name="HipLink2" file="Hip_Link2.stl" scale="0.001 0.001 0.001" />
        <mesh name="Thigh" file="Thigh.stl" scale="0.001 0.001 0.001" />
        <mesh name="Left_Shank" file="Left_Shank.stl" scale="0.001 0.001 0.001" />
        <mesh name="Right_Shank" file="Right_Shank.stl" scale="0.001 0.001 0.001" />
        <!--   Ankle and Foot stl file  -->
        <mesh name="Ankle_Joint" file="Ankle_Joint.stl" scale="0.001 0.001 0.001" />
        <mesh name="Foot" file="Foot.stl" scale="0.001 0.001 0.001" />
    </asset>
    <visual>
        <headlight diffuse="0.6 0.6 0.6" ambient="0.3 0.3 0.3" specular="0 0 0" />
        <rgba haze="0.15 0.25 0.35 1" />
        <global azimuth="-130" elevation="-20" />
    </visual>

    <asset>
        <texture builtin="gradient" height="100" rgb1=".4 .5 .6" rgb2="0 0 0" type="skybox" width="100" />
        <texture name="texplane" type="2d" builtin="checker" rgb1=".2 .3 .4" rgb2=".1 0.15 0.2" width="100" height="100" />
        <material name="MatPlane" reflectance="0.5" texture="texplane" texrepeat="1 1" texuniform="true" />
    </asset>



    <worldbody>
        <geom name="ground" pos="0 0 0" size="5 5 0.05" type="plane" material = "MatPlane" friction= "1 1 0.1" condim="3" conaffinity="1" contype="1" group="2" rgba="0.8 0.9 0.8 1" />

        <light cutoff="1000" diffuse="1 1 1" dir="-0 0 -1.3" directional="true" exponent="1" pos="0 0 1.3" specular=".1 .1 .1" castshadow="false" />
        <!--   Projection of the Pelvis Ceter on the Ground -->
        <site name="ZMP_est" pos="0 0 0" size="0.02" rgba="0 1 0 1"/>
        <site name="ZMP_ref" pos="0 0 0" size="0.02" rgba="1 0 0 1"/>
        <site name="COM_ref" pos="0 0 0" size="0.02" rgba="0 0 1 1"/>

        <!--   Torso -->
        <body name="Torso" pos="0 0 0.81" euler="0 0 -90">
            <geom type="mesh" class="transparent" mesh="Torso" />

            <freejoint name="root"/>
            <inertial pos="0 0 -8.692E-3" mass="5.803" fullinertia="1.005E-1 1.343E-1 6.599E-2 -605.112E-9 9367.185E-9 -10103.262E-9"/>
            <camera name="track" pos="0 1 1" xyaxes="1 0 0 0 1 2" mode="track"/>
            <site name="IMU" type = "box" pos="0 0 0.05" euler="0 0 90" size="0.01 0.01 0.01" rgba="1 0 0 1"/>

            <!--   Right leg kinematic chain  -->
            <body name="Right_Hip_link01" pos="90.397E-3 0 -81.608E-3" euler="0 90 90"> <!--   "0 105 90"  -->
                <!--   Hip link 1, set euler angle to rotate the body   -->
                <joint type="hinge" name="Right_Hip_Pitch" axis="0 0 -1" pos="0 0 -0.075" range="-90 90" class = "AK109_actuator"/>
                <geom type="mesh" class="visual" mesh="HipLink1" />
                <inertial pos="5.274E-3 0.583E-3 61.205E-3" mass="1.770" fullinertia="3.213E-3 3.368E-3 2.277E-3 5536E-9 -1.28E-4 2470.492E-9" />

                <body name="Right_Hip_link02" pos="-52E-3 0 75E-3" euler="90 -90 -90"> <!--   "90 -90 -75"  -->
                    <!--   Hip link 1, set euler angle to rotate the body   -->
                    <joint type="hinge" name="Right_Hip_Roll" axis="0 0 -1" pos="0 0 0" range="-90 90" class = "AK109_actuator"/>
                    <geom type="mesh" class="visual" mesh="HipLink2" />
                    <inertial pos="0.03E-3 71.886E-3 -51.989E-3" mass="1.117" fullinertia="2.793E-3 1.705E-3 2.101E-3 -3650.985E-9 -807.627E-9 7163.808E-9" />

                    <body name="Right_Thigh" pos="0 124.5E-3 -52E-3" euler="90 0 90">
                        <!--   Hip link 1, set euler angle to rotate the body   -->
                        <joint type="hinge" name="Right_Hip_Yaw" axis="0 0 1" pos="0 0 0" range="-90 90" class = "AK7010_actuator"/>
                        <geom type="mesh" class="visual" mesh="Thigh" />
                        <inertial pos="0.025E-3 -13.667E-3 -160.484E-3" mass="1.9177" fullinertia="1.2E-2 1.245E-2 2.07E-3 2061.057E-9 3103.541E-9 -1E-3" />

                        <body name="Right_Shank" pos="0 21E-3 -200E-3" euler="-90 0 90">
                            <!--   Hip link 1, set euler angle to rotate the body   -->
                            <joint type="hinge" name="Right_Knee" axis="0 0 -1" pos="0 0 0" range="-90 90" class = "AK109_actuator"/>
                            <geom type="mesh" class="visual" mesh="Right_Shank" />
                            <inertial pos="161.205E-3 9.33E-3 -17.018E-3" mass="1.669" fullinertia=" 1.369E-3 1.512E-2 1.493E-2 6.644E-4 8.379E-4 12203.356E-9"/>

                            <body name="Right_Ankle_Joint" pos="337E-3 27.1E-3 -17.1E-3" euler="90 0 -90">
                                <!--   Hip link 1, set euler angle to rotate the body   -->
                                <joint type="hinge" name="Right_Ankle_Roll" axis="0 0 -1" pos="0 0 0" range="-90 90" class = "AK606_actuator"/>
                                <geom type="mesh" class="visual" mesh="Ankle_Joint" />
                                <inertial pos="0 0 27E-3" mass="0.113" fullinertia="14352.686E-9 19761.129E-9 9953.085E-9 0 0 0" />

                                <body name="Right_Foot" pos="-15E-3 0 27E-3" euler="90 90 0">
                                    <!--   Hip link 1, set euler angle to rotate the body   -->
                                    <joint type="hinge" name="Right_Ankle_Pitch" axis="0 0 1" pos="0 0 0" range="-90 90" class = "AK606_actuator"/>
                                    <geom name = "Right_Foot" type="mesh" class="visual" mesh="Foot" />
                                    <inertial pos="26.518E-3 -11.518E-3 16.827E-3" mass="0.28" fullinertia="4.266E-4 1.520E-4 3.89E-4 28868.676E-9 6621.189E-9 -5893.661E-9" />
                                    <site name="Right_Force_Torque_Sensor" type = "box" pos="30E-3 0 15E-3" euler="0 -90 -90" size="0.015 0.015 0.015" rgba="1 0 0 1"/>
                                </body>
                            </body>
                        </body>
                    </body>
                </body>
            </body>

            <!--   Left leg kinematic chain  -->
            <body name="Left_Hip_link01" pos="-90.397E-3 0 -81.608E-3" euler="0 -90 -90"> <!--   "0 -105 -90"  -->
                <!--   Hip link 1, set euler angle to rotate the body   -->
                <joint type="hinge" name="Left_Hip_Pitch" axis="0 0 1" pos="0 0 -0.075" range="-90 90" class = "AK109_actuator"/>
                <geom type="mesh" class="visual" mesh="HipLink1" />
               <inertial pos="5.274E-3 0.583E-3 61.205E-3" mass="1.770" fullinertia="3.213E-3 3.368E-3 2.277E-3 5536E-9 -1.28E-4 2470.492E-9" />

                <body name="Left_Hip_link02" pos="-52E-3 0 75E-3" euler="90 -90 -90"> <!--   "90 -90 -75"  -->
                    <!--   Hip link 1, set euler angle to rotate the body   -->
                    <joint type="hinge" name="Left_Hip_Roll" axis="0 0 1" pos="0 0 0" range="-90 90" class = "AK109_actuator"/>
                    <geom type="mesh" class="visual" mesh="HipLink2" />
                    <inertial pos="0.03E-3 71.886E-3 -51.989E-3" mass="1.117" fullinertia="2.793E-3 1.705E-3 2.101E-3 -3650.985E-9 -807.627E-9 7163.808E-9" />

                    <body name="Left_Thigh" pos="0 124.5E-3 -52E-3" euler="90 0 90">
                        <!--   Hip link 1, set euler angle to rotate the body   -->
                        <joint type="hinge" name="Left_Hip_Yaw" axis="0 0 1" pos="0 0 0" range="-90 90" class = "AK7010_actuator"/>
                        <geom type="mesh" class="visual" mesh="Thigh" />
                        <inertial pos="0.025E-3 -13.667E-3 -160.484E-3" mass="1.9177" fullinertia="1.2E-2 1.245E-2 2.07E-3 2061.057E-9 3103.541E-9 -1E-3" />

                        <body name="Left_Shank" pos="0 21E-3 -200E-3" euler="90 0 180">
                            <!--   Hip link 1, set euler angle to rotate the body   -->
                            <joint type="hinge" name="Left_Knee" axis="0 0 -1" pos="0 0 0" range="-90 90" class = "AK109_actuator"/>
                            <geom type="mesh" class="visual" mesh="Left_Shank" />
                            <inertial pos="-9.33E-3 161.205E-3 17.018E-3" mass="1.669" fullinertia="1.512E-2 1.369E-3 1.493E-2 6.644E-4 12203.356E-9 -8.379E-4"/>

                            <body name="Left_Ankle_Joint" pos="-27.1E-3 337E-3 20.9E-3" euler="0 90 0">
                                <!--   Hip link 1, set euler angle to rotate the body   -->
                                <joint type="hinge" name="Left_Ankle_Roll" axis="0 0 -1" pos="0 0 0" range="-90 90" class = "AK606_actuator"/>
                                <geom type="mesh" class="visual" mesh="Ankle_Joint" />
                                 <inertial pos="0 0 27E-3" mass="0.113" fullinertia="14352.686E-9 19761.129E-9 9953.085E-9 0 0 0" />

                                <body name="Left_Foot" pos="-15E-3 0 27E-3" euler="90 90 0">
                                    <!--   Hip link 1, set euler angle to rotate the body   -->
                                    <joint type="hinge" name="Left_Ankle_Pitch" axis="0 0 1" pos="0 0 0" range="-90 90" class = "AK606_actuator"/>
                                    <geom name = "Left_Foot" type="mesh" class="visual" mesh="Foot" />
                                    <inertial pos="26.518E-3 -11.518E-3 16.827E-3" mass="0.28" fullinertia="4.266E-4 1.520E-4 3.89E-4 28868.676E-9 6621.189E-9 -5893.661E-9" />
                                    <site name="Left_Force_Torque_Sensor" type = "box" pos="30E-3 0 15E-3" euler="0 -90 -90" size="0.015 0.015 0.015" rgba="1 0 0 1"/>
                                </body>
                            </body>
                        </body>
                    </body>
                </body>
            </body>
        </body>
        <!--   End of 2 legs  -->
    </worldbody>

    <contact>
        <exclude body1="Torso" body2="Right_Hip_link01" />
        <exclude body1="Torso" body2="Right_Hip_link02" />
        <exclude body1="Torso" body2="Left_Thigh" />
        <exclude body1="Right_Hip_link01" body2="Right_Hip_link02" />
        <exclude body1="Right_Hip_link02" body2="Left_Thigh" />
        <exclude body1="Left_Thigh" body2="Left_Shank" />
        <exclude body1="Left_Shank" body2="Left_Ankle_Joint" />
        <exclude body1="Left_Ankle_Joint" body2="Left_Foot" />
        <exclude body1="Torso" body2="Left_Hip_link01" />
        <exclude body1="Torso" body2="Left_Hip_link02" />
        <exclude body1="Torso" body2="Right_Thigh" />
        <exclude body1="Left_Hip_link01" body2="Left_Hip_link02" />
        <exclude body1="Left_Hip_link02" body2="Right_Thigh" />
        <exclude body1="Right_Thigh" body2="Left_Shank" />
        <exclude body1="Left_Shank" body2="Left_Ankle_Joint" />
        <exclude body1="Left_Ankle_Joint" body2="Left_Foot" />
        <exclude body1="Left_Thigh" body2="Right_Thigh" />
        <exclude body1="Right_Shank" body2="Left_Shank" />
    </contact>


    <actuator>
        <motor name="Right_Hip_Pitch_m" joint="Right_Hip_Pitch" ctrlrange="-120 120" />        
        <motor name="Right_Hip_Roll_m" joint="Right_Hip_Roll" ctrlrange="-45 45" />        
        <motor name="Right_Hip_Yaw_m" joint="Right_Hip_Yaw" ctrlrange="-24 24" />
        <motor name="Right_Knee_m" joint="Right_Knee" ctrlrange="-60 60" />
        <motor name="Right_Ank_Pitch_m" joint="Right_Ankle_Pitch" ctrlrange="-30 30" />
        <motor name="Right_Ank_Roll_m" joint="Right_Ankle_Roll" ctrlrange="-30 30" />

        <motor name="Left_Hip_Pitch_m" joint="Left_Hip_Pitch" ctrlrange="-120 120" />
        <motor name="Left_Hip_Roll_m" joint="Left_Hip_Roll" ctrlrange="-45 45" />
        <motor name="Left_Hip_Yaw_m" joint="Left_Hip_Yaw" ctrlrange="-24 24" />
        <motor name="Left_Knee_m" joint="Left_Knee" ctrlrange="-60 60" />
        <motor name="Left_Ank_Pitch_m" joint="Left_Ankle_Pitch" ctrlrange="-30 30" />
        <motor name="Left_Ank_Roll_m" joint="Left_Ankle_Roll" ctrlrange="-30 30" />
    </actuator>

    <sensor>
        <accelerometer name="accel" site="IMU"/>
        <gyro name="gyro" site="IMU"/>
        <velocimeter name="velmeter" site="IMU"/>

        <force name="left_foot_force" site="Left_Force_Torque_Sensor"/>
        <torque name="left_foot_torque" site="Left_Force_Torque_Sensor"/>

        <force name="right_foot_force" site="Right_Force_Torque_Sensor"/>
        <torque name="right_foot_torque" site="Right_Force_Torque_Sensor"/>
    </sensor>
</mujoco>